Workbook

Sheet Resumo
A1: Categoria | B1: Subcategoria | C1: Dafu - menor preço unit. | D1: Dafu - maior preço unit. | E1: Zhang - menor preço unit. | F1: Zhang - maior preço unit. | G1: Varejo referência (unid.) | H1: Mais barato no atacado | I1: Leitura | J1: Outros BR - menor preço unit. | K1: China - menor custo estimado posto
A2: Cílios | B2: Extensão fio a fio | C2: =IFERROR(_xlfn.MINIFS(Dafu!$H:$H,Dafu!$A:$A,A2,Dafu!$B:$B,B2),"") -> 11 | D2: =IFERROR(_xlfn.MAXIFS(Dafu!$H:$H,Dafu!$A:$A,A2,Dafu!$B:$B,B2),"") -> 22 | E2: =IFERROR(_xlfn.MINIFS(Zhang!$E:$E,Zhang!$A:$A,A2,Zhang!$B:$B,B2),"") -> 0 | F2: =IFERROR(_xlfn.MAXIFS(Zhang!$E:$E,Zhang!$A:$A,A2,Zhang!$B:$B,B2),"") -> 0 | G2: =IFERROR(_xlfn.MINIFS(Referencia!$D:$D,Referencia!$A:$A,A2,Referencia!$B:$B,B2),"") -> 19.8 | H2: =IF(AND(N(C2)=0,N(E2)=0),"-",IF(N(E2)=0,"Dafu",IF(N(C2)=0,"Zhang",IF(C2<=E2,"Dafu","Zhang")))) -> Dafu | I2: Só a Dafu tem (Fadvan e DeceMars). Bandeja YY a R$11 contra ~R$20-25 no varejo: margem folgada. É o item de maior valor por caixa. | J2: =IFERROR(_xlfn.MINIFS('Outros fornecedores'!$J:$J,'Outros fornecedores'!$A:$A,"Brasil",'Outros fornecedores'!$B:$B,A2,'Outros fornecedores'!$C:$C,B2),"") -> 20.55 | K2: =IFERROR(_xlfn.MINIFS('Outros fornecedores'!$J:$J,'Outros fornecedores'!$A:$A,"China",'Outros fornecedores'!$B:$B,A2,'Outros fornecedores'!$C:$C,B2),"") -> 9.994
A3: Cílios | B3: Tufinho / cluster | C3: =IFERROR(_xlfn.MINIFS(Dafu!$H:$H,Dafu!$A:$A,A3,Dafu!$B:$B,B3),"") -> 1 | D3: =IFERROR(_xlfn.MAXIFS(Dafu!$H:$H,Dafu!$A:$A,A3,Dafu!$B:$B,B3),"") -> 15 | E3: =IFERROR(_xlfn.MINIFS(Zhang!$E:$E,Zhang!$A:$A,A3,Zhang!$B:$B,B3),"") -> 3.7 | F3: =IFERROR(_xlfn.MAXIFS(Zhang!$E:$E,Zhang!$A:$A,A3,Zhang!$B:$B,B3),"") -> 9 | G3: =IFERROR(_xlfn.MINIFS(Referencia!$D:$D,Referencia!$A:$A,A3,Referencia!$B:$B,B3),"") -> 15.68 | H3: =IF(AND(N(C3)=0,N(E3)=0),"-",IF(N(E3)=0,"Dafu",IF(N(C3)=0,"Zhang",IF(C3<=E3,"Dafu","Zhang")))) -> Dafu | I3: Zhang tem tufinho New Show de R$4,00 a R$4,50 (caixas c/10-12) – o mais barato. Dafu começa em R$3,60 mas os modelos comparáveis ficam entre R$5 e R$6,50; as mega caixas Dafu (R$9,58-13) não têm equivalente na Zhang. | J3: =IFERROR(_xlfn.MINIFS('Outros fornecedores'!$J:$J,'Outros fornecedores'!$A:$A,"Brasil",'Outros fornecedores'!$B:$B,A3,'Outros fornecedores'!$C:$C,B3),"") -> 2.19 | K3: =IFERROR(_xlfn.MINIFS('Outros fornecedores'!$J:$J,'Outros fornecedores'!$A:$A,"China",'Outros fornecedores'!$B:$B,A3,'Outros fornecedores'!$C:$C,B3),"") -> 9.69
A4: Cílios | B4: Kit tufinho | C4: =IFERROR(_xlfn.MINIFS(Dafu!$H:$H,Dafu!$A:$A,A4,Dafu!$B:$B,B4),"") -> 0 | D4: =IFERROR(_xlfn.MAXIFS(Dafu!$H:$H,Dafu!$A:$A,A4,Dafu!$B:$B,B4),"") -> 0 | E4: =IFERROR(_xlfn.MINIFS(Zhang!$E:$E,Zhang!$A:$A,A4,Zhang!$B:$B,B4),"") -> 12 | F4: =IFERROR(_xlfn.MAXIFS(Zhang!$E:$E,Zhang!$A:$A,A4,Zhang!$B:$B,B4),"") -> 16.5 | G4: =IFERROR(_xlfn.MINIFS(Referencia!$D:$D,Referencia!$A:$A,A4,Referencia!$B:$B,B4),"") -> 0 | H4: =IF(AND(N(C4)=0,N(E4)=0),"-",IF(N(E4)=0,"Dafu",IF(N(C4)=0,"Zhang",IF(C4<=E4,"Dafu","Zhang")))) -> Zhang | I4: Zhang: kits Sabrina Sato/Love Rain/New Show R$12-16,50. Dafu: kits com pinça e cola R$19,80-20 (mais completos). | J4: =IFERROR(_xlfn.MINIFS('Outros fornecedores'!$J:$J,'Outros fornecedores'!$A:$A,"Brasil",'Outros fornecedores'!$B:$B,A4,'Outros fornecedores'!$C:$C,B4),"") -> 0 | K4: =IFERROR(_xlfn.MINIFS('Outros fornecedores'!$J:$J,'Outros fornecedores'!$A:$A,"China",'Outros fornecedores'!$B:$B,A4,'Outros fornecedores'!$C:$C,B4),"") -> 0
A5: Cílios | B5: Kit completo | C5: =IFERROR(_xlfn.MINIFS(Dafu!$H:$H,Dafu!$A:$A,A5,Dafu!$B:$B,B5),"") -> 19.8 | D5: =IFERROR(_xlfn.MAXIFS(Dafu!$H:$H,Dafu!$A:$A,A5,Dafu!$B:$B,B5),"") -> 20 | E5: =IFERROR(_xlfn.MINIFS(Zhang!$E:$E,Zhang!$A:$A,A5,Zhang!$B:$B,B5),"") -> 0 | F5: =IFERROR(_xlfn.MAXIFS(Zhang!$E:$E,Zhang!$A:$A,A5,Zhang!$B:$B,B5),"") -> 0 | G5: =IFERROR(_xlfn.MINIFS(Referencia!$D:$D,Referencia!$A:$A,A5,Referencia!$B:$B,B5),"") -> 29.99 | H5: =IF(AND(N(C5)=0,N(E5)=0),"-",IF(N(E5)=0,"Dafu",IF(N(C5)=0,"Zhang",IF(C5<=E5,"Dafu","Zhang")))) -> Dafu | I5: Ver linha acima: Dafu tem o kit completo com pinça e cola. | J5: =IFERROR(_xlfn.MINIFS('Outros fornecedores'!$J:$J,'Outros fornecedores'!$A:$A,"Brasil",'Outros fornecedores'!$B:$B,A5,'Outros fornecedores'!$C:$C,B5),"") -> 16.665833 | K5: =IFERROR(_xlfn.MINIFS('Outros fornecedores'!$J:$J,'Outros fornecedores'!$A:$A,"China",'Outros fornecedores'!$B:$B,A5,'Outros fornecedores'!$C:$C,B5),"") -> 0
A6: Cílios | B6: Postiço em tira | C6: =IFERROR(_xlfn.MINIFS(Dafu!$H:$H,Dafu!$A:$A,A6,Dafu!$B:$B,B6),"") -> 5 | D6: =IFERROR(_xlfn.MAXIFS(Dafu!$H:$H,Dafu!$A:$A,A6,Dafu!$B:$B,B6),"") -> 7.5 | E6: =IFERROR(_xlfn.MINIFS(Zhang!$E:$E,Zhang!$A:$A,A6,Zhang!$B:$B,B6),"") -> 3 | F6: =IFERROR(_xlfn.MAXIFS(Zhang!$E:$E,Zhang!$A:$A,A6,Zhang!$B:$B,B6),"") -> 9 | G6: =IFERROR(_xlfn.MINIFS(Referencia!$D:$D,Referencia!$A:$A,A6,Referencia!$B:$B,B6),"") -> 0 | H6: =IF(AND(N(C6)=0,N(E6)=0),"-",IF(N(E6)=0,"Dafu",IF(N(C6)=0,"Zhang",IF(C6<=E6,"Dafu","Zhang")))) -> Zhang | I6: Zhang bem mais barata: Amor Anjo 1 par R$3,50; Macrilan 5 pares R$3,00. Dafu R$5-7,50. | J6: =IFERROR(_xlfn.MINIFS('Outros fornecedores'!$J:$J,'Outros fornecedores'!$A:$A,"Brasil",'Outros fornecedores'!$B:$B,A6,'Outros fornecedores'!$C:$C,B6),"") -> 1.5 | K6: =IFERROR(_xlfn.MINIFS('Outros fornecedores'!$J:$J,'Outros fornecedores'!$A:$A,"China",'Outros fornecedores'!$B:$B,A6,'Outros fornecedores'!$C:$C,B6),"") -> 0
A7: Cílios | B7: Cola | C7: =IFERROR(_xlfn.MINIFS(Dafu!$H:$H,Dafu!$A:$A,A7,Dafu!$B:$B,B7),"") -> 4.5 | D7: =IFERROR(_xlfn.MAXIFS(Dafu!$H:$H,Dafu!$A:$A,A7,Dafu!$B:$B,B7),"") -> 10 | E7: =IFERROR(_xlfn.MINIFS(Zhang!$E:$E,Zhang!$A:$A,A7,Zhang!$B:$B,B7),"") -> 1.66 | F7: =IFERROR(_xlfn.MAXIFS(Zhang!$E:$E,Zhang!$A:$A,A7,Zhang!$B:$B,B7),"") -> 8 | G7: =IFERROR(_xlfn.MINIFS(Referencia!$D:$D,Referencia!$A:$A,A7,Referencia!$B:$B,B7),"") -> 0 | H7: =IF(AND(N(C7)=0,N(E7)=0),"-",IF(N(E7)=0,"Dafu",IF(N(C7)=0,"Zhang",IF(C7<=E7,"Dafu","Zhang")))) -> Zhang | I7: Nexxo (caixa fechada): Duo Eye R$1,54 e Salon Pro 30ml R$4,20 – a Salon Pro vende ~R$25-30 no varejo. Zhang Eye R$1,66 é a melhor sem caixa fechada. | J7: =IFERROR(_xlfn.MINIFS('Outros fornecedores'!$J:$J,'Outros fornecedores'!$A:$A,"Brasil",'Outros fornecedores'!$B:$B,A7,'Outros fornecedores'!$C:$C,B7),"") -> 1.5416667 | K7: =IFERROR(_xlfn.MINIFS('Outros fornecedores'!$J:$J,'Outros fornecedores'!$A:$A,"China",'Outros fornecedores'!$B:$B,A7,'Outros fornecedores'!$C:$C,B7),"") -> 0
A8: Unhas | B8: Unha postiça | C8: =IFERROR(_xlfn.MINIFS(Dafu!$H:$H,Dafu!$A:$A,A8,Dafu!$B:$B,B8),"") -> 1.83 | D8: =IFERROR(_xlfn.MAXIFS(Dafu!$H:$H,Dafu!$A:$A,A8,Dafu!$B:$B,B8),"") -> 18 | E8: =IFERROR(_xlfn.MINIFS(Zhang!$E:$E,Zhang!$A:$A,A8,Zhang!$B:$B,B8),"") -> 6.25 | F8: =IFERROR(_xlfn.MAXIFS(Zhang!$E:$E,Zhang!$A:$A,A8,Zhang!$B:$B,B8),"") -> 9 | G8: =IFERROR(_xlfn.MINIFS(Referencia!$D:$D,Referencia!$A:$A,A8,Referencia!$B:$B,B8),"") -> 4.89 | H8: =IF(AND(N(C8)=0,N(E8)=0),"-",IF(N(E8)=0,"Dafu",IF(N(C8)=0,"Zhang",IF(C8<=E8,"Dafu","Zhang")))) -> Dafu | I8: Press-on: Dafu R$1,83-6 segue forte; Zaxapp R$2,33-2,50. Tips para alongamento: Fonte da Beleza R$6 (120 un). Nexxo tem cartelinha simples a R$0,37 (promo). | J8: =IFERROR(_xlfn.MINIFS('Outros fornecedores'!$J:$J,'Outros fornecedores'!$A:$A,"Brasil",'Outros fornecedores'!$B:$B,A8,'Outros fornecedores'!$C:$C,B8),"") -> 0.37083333 | K8: =IFERROR(_xlfn.MINIFS('Outros fornecedores'!$J:$J,'Outros fornecedores'!$A:$A,"China",'Outros fornecedores'!$B:$B,A8,'Outros fornecedores'!$C:$C,B8),"") -> 4.408
A9: Unhas | B9: Esmalte | C9: =IFERROR(_xlfn.MINIFS(Dafu!$H:$H,Dafu!$A:$A,A9,Dafu!$B:$B,B9),"") -> 3 | D9: =IFERROR(_xlfn.MAXIFS(Dafu!$H:$H,Dafu!$A:$A,A9,Dafu!$B:$B,B9),"") -> 7.5 | E9: =IFERROR(_xlfn.MINIFS(Zhang!$E:$E,Zhang!$A:$A,A9,Zhang!$B:$B,B9),"") -> 1.5 | F9: =IFERROR(_xlfn.MAXIFS(Zhang!$E:$E,Zhang!$A:$A,A9,Zhang!$B:$B,B9),"") -> 1.75 | G9: =IFERROR(_xlfn.MINIFS(Referencia!$D:$D,Referencia!$A:$A,A9,Referencia!$B:$B,B9),"") -> 0 | H9: =IF(AND(N(C9)=0,N(E9)=0),"-",IF(N(E9)=0,"Dafu",IF(N(C9)=0,"Zhang",IF(C9<=E9,"Dafu","Zhang")))) -> Zhang | I9: Zhang: esmalte rasgável Love Rain R$1,50-1,75 (o mais barato). Dafu: R$3-7,50, maior variedade de cores. | J9: =IFERROR(_xlfn.MINIFS('Outros fornecedores'!$J:$J,'Outros fornecedores'!$A:$A,"Brasil",'Outros fornecedores'!$B:$B,A9,'Outros fornecedores'!$C:$C,B9),"") -> 0 | K9: =IFERROR(_xlfn.MINIFS('Outros fornecedores'!$J:$J,'Outros fornecedores'!$A:$A,"China",'Outros fornecedores'!$B:$B,A9,'Outros fornecedores'!$C:$C,B9),"") -> 0
A10: Unhas | B10: Esmalte em gel | C10: =IFERROR(_xlfn.MINIFS(Dafu!$H:$H,Dafu!$A:$A,A10,Dafu!$B:$B,B10),"") -> 8 | D10: =IFERROR(_xlfn.MAXIFS(Dafu!$H:$H,Dafu!$A:$A,A10,Dafu!$B:$B,B10),"") -> 11 | E10: =IFERROR(_xlfn.MINIFS(Zhang!$E:$E,Zhang!$A:$A,A10,Zhang!$B:$B,B10),"") -> 5.5 | F10: =IFERROR(_xlfn.MAXIFS(Zhang!$E:$E,Zhang!$A:$A,A10,Zhang!$B:$B,B10),"") -> 7.83 | G10: =IFERROR(_xlfn.MINIFS(Referencia!$D:$D,Referencia!$A:$A,A10,Referencia!$B:$B,B10),"") -> 18.99 | H10: =IF(AND(N(C10)=0,N(E10)=0),"-",IF(N(E10)=0,"Dafu",IF(N(C10)=0,"Zhang",IF(C10<=E10,"Dafu","Zhang")))) -> Zhang | I10: Fonte da Beleza R$5,00 (dúzia) – mais barato que Zhang (R$5,50) e Dafu (R$8-11). Dafu é marca conhecida (~R$19 no varejo). | J10: =IFERROR(_xlfn.MINIFS('Outros fornecedores'!$J:$J,'Outros fornecedores'!$A:$A,"Brasil",'Outros fornecedores'!$B:$B,A10,'Outros fornecedores'!$C:$C,B10),"") -> 5 | K10: =IFERROR(_xlfn.MINIFS('Outros fornecedores'!$J:$J,'Outros fornecedores'!$A:$A,"China",'Outros fornecedores'!$B:$B,A10,'Outros fornecedores'!$C:$C,B10),"") -> 5.871
A11: Unhas | B11: Cola | C11: =IFERROR(_xlfn.MINIFS(Dafu!$H:$H,Dafu!$A:$A,A11,Dafu!$B:$B,B11),"") -> 2.25 | D11: =IFERROR(_xlfn.MAXIFS(Dafu!$H:$H,Dafu!$A:$A,A11,Dafu!$B:$B,B11),"") -> 2.25 | E11: =IFERROR(_xlfn.MINIFS(Zhang!$E:$E,Zhang!$A:$A,A11,Zhang!$B:$B,B11),"") -> 4 | F11: =IFERROR(_xlfn.MAXIFS(Zhang!$E:$E,Zhang!$A:$A,A11,Zhang!$B:$B,B11),"") -> 4 | G11: =IFERROR(_xlfn.MINIFS(Referencia!$D:$D,Referencia!$A:$A,A11,Referencia!$B:$B,B11),"") -> 0 | H11: =IF(AND(N(C11)=0,N(E11)=0),"-",IF(N(E11)=0,"Dafu",IF(N(C11)=0,"Zhang",IF(C11<=E11,"Dafu","Zhang")))) -> Dafu | I11: Zaxapp R$1,00 (3g, kit 20) e Nexxo R$1,27 (promo) / R$1,33 (caixa fechada). Dafu R$2,25. | J11: =IFERROR(_xlfn.MINIFS('Outros fornecedores'!$J:$J,'Outros fornecedores'!$A:$A,"Brasil",'Outros fornecedores'!$B:$B,A11,'Outros fornecedores'!$C:$C,B11),"") -> 0.9995 | K11: =IFERROR(_xlfn.MINIFS('Outros fornecedores'!$J:$J,'Outros fornecedores'!$A:$A,"China",'Outros fornecedores'!$B:$B,A11,'Outros fornecedores'!$C:$C,B11),"") -> 0
A12: Unhas | B12: Gel | C12: =IFERROR(_xlfn.MINIFS(Dafu!$H:$H,Dafu!$A:$A,A12,Dafu!$B:$B,B12),"") -> 4 | D12: =IFERROR(_xlfn.MAXIFS(Dafu!$H:$H,Dafu!$A:$A,A12,Dafu!$B:$B,B12),"") -> 11 | E12: =IFERROR(_xlfn.MINIFS(Zhang!$E:$E,Zhang!$A:$A,A12,Zhang!$B:$B,B12),"") -> 0 | F12: =IFERROR(_xlfn.MAXIFS(Zhang!$E:$E,Zhang!$A:$A,A12,Zhang!$B:$B,B12),"") -> 0 | G12: =IFERROR(_xlfn.MINIFS(Referencia!$D:$D,Referencia!$A:$A,A12,Referencia!$B:$B,B12),"") -> 0 | H12: =IF(AND(N(C12)=0,N(E12)=0),"-",IF(N(E12)=0,"Dafu",IF(N(C12)=0,"Zhang",IF(C12<=E12,"Dafu","Zhang")))) -> Dafu | I12: Fonte da Beleza: painting gel R$5 e gel construtor X&D R$6. Dafu: painting R$6, construtor R$8. | J12: =IFERROR(_xlfn.MINIFS('Outros fornecedores'!$J:$J,'Outros fornecedores'!$A:$A,"Brasil",'Outros fornecedores'!$B:$B,A12,'Outros fornecedores'!$C:$C,B12),"") -> 5 | K12: =IFERROR(_xlfn.MINIFS('Outros fornecedores'!$J:$J,'Outros fornecedores'!$A:$A,"China",'Outros fornecedores'!$B:$B,A12,'Outros fornecedores'!$C:$C,B12),"") -> 0
A13: Unhas | B13: Preparação / base / top | C13: =IFERROR(_xlfn.MINIFS(Dafu!$H:$H,Dafu!$A:$A,A13,Dafu!$B:$B,B13),"") -> 5.5 | D13: =IFERROR(_xlfn.MAXIFS(Dafu!$H:$H,Dafu!$A:$A,A13,Dafu!$B:$B,B13),"") -> 12 | E13: =IFERROR(_xlfn.MINIFS(Zhang!$E:$E,Zhang!$A:$A,A13,Zhang!$B:$B,B13),"") -> 0 | F13: =IFERROR(_xlfn.MAXIFS(Zhang!$E:$E,Zhang!$A:$A,A13,Zhang!$B:$B,B13),"") -> 0 | G13: =IFERROR(_xlfn.MINIFS(Referencia!$D:$D,Referencia!$A:$A,A13,Referencia!$B:$B,B13),"") -> 0 | H13: =IF(AND(N(C13)=0,N(E13)=0),"-",IF(N(E13)=0,"Dafu",IF(N(C13)=0,"Zhang",IF(C13<=E13,"Dafu","Zhang")))) -> Dafu | I13: Fonte da Beleza bem mais barata: base/top X&D R$4, prep 120ml R$4 e 500ml R$9. Dafu R$7,50-12. | J13: =IFERROR(_xlfn.MINIFS('Outros fornecedores'!$J:$J,'Outros fornecedores'!$A:$A,"Brasil",'Outros fornecedores'!$B:$B,A13,'Outros fornecedores'!$C:$C,B13),"") -> 4 | K13: =IFERROR(_xlfn.MINIFS('Outros fornecedores'!$J:$J,'Outros fornecedores'!$A:$A,"China",'Outros fornecedores'!$B:$B,A13,'Outros fornecedores'!$C:$C,B13),"") -> 0
... A16: Unhas | B16: Equipamento | C16: =IFERROR(_xlfn.MINIFS(Dafu!$H:$H,Dafu!$A:$A,A16,Dafu!$B:$B,B16),"") -> 7 | D16: =IFERROR(_xlfn.MAXIFS(Dafu!$H:$H,Dafu!$A:$A,A16,Dafu!$B:$B,B16),"") -> 220 | E16: =IFERROR(_xlfn.MINIFS(Zhang!$E:$E,Zhang!$A:$A,A16,Zhang!$B:$B,B16),"") -> 0 | F16: =IFERROR(_xlfn.MAXIFS(Zhang!$E:$E,Zhang!$A:$A,A16,Zhang!$B:$B,B16),"") -> 0 | G16: =IFERROR(_xlfn.MINIFS(Referencia!$D:$D,Referencia!$A:$A,A16,Referencia!$B:$B,B16),"") -> 0 | H16: =IF(AND(N(C16)=0,N(E16)=0),"-",IF(N(E16)=0,"Dafu",IF(N(C16)=0,"Zhang",IF(C16<=E16,"Dafu","Zhang")))) -> Dafu | I16: Fonte da Beleza: mini cabine R$5,50, lanterna R$18, motor caneta R$20, cabine R$60. Dafu: mini cabine R$9-11, cabines R$70-75. | J16: =IFERROR(_xlfn.MINIFS('Outros fornecedores'!$J:$J,'Outros fornecedores'!$A:$A,"Brasil",'Outros fornecedores'!$B:$B,A16,'Outros fornecedores'!$C:$C,B16),"") -> 5.5 | K16: =IFERROR(_xlfn.MINIFS('Outros fornecedores'!$J:$J,'Outros fornecedores'!$A:$A,"China",'Outros fornecedores'!$B:$B,A16,'Outros fornecedores'!$C:$C,B16),"") -> 0
A18: Mínimos e máximos calculados das abas Dafu e Zhang (preço unitário de atacado). Zero/vazio = fornecedor não tem o item.
A19: Dafu: 8% de desconto em caixa fechada (não aplicado). Zhang: preços públicos do site em 22/10/2026, sem login.

Sheet Outros fornecedores
A1: Origem | B1: Categoria | C1: Subcategoria | D1: Fornecedor | E1: Produto | F1: Marca | G1: Unid. no lote | H1: Preço do lote (R$) | I1: Preço unit. (R$) | J1: Custo estimado posto no Brasil (R$) | K1: Obs. | L1: Link | N1: Fator custo importação China
A2: Brasil | B2: Cílios | C2: Tufinho / cluster | D2: Maquiagem Atacado (SP) | E2: Tufinho tufos 14mm QBM670 | F2: - | G2: 1 | H2: 2.19 | I2: =H2/G2 -> 2.19 | J2: =I2*IF(A2="China",$O$2,1) -> 2.19 | K2: Unidade; Pix R$2,08 | L2: https://www.maquiagematacado.com.br/cilios-posticos | N2: Multiplicador sobre FOB | O2: 1.9
A3: Brasil | B3: Cílios | C3: Tufinho / cluster | D3: Distribuidora JCF | E3: Cílios em tufos 14mm CCT32 (12 un) | F3: Meilys | G3: 12 | H3: 35.9 | I3: =H3/G3 -> 2.9916667 | J3: =I3*IF(A3="China",$O$2,1) -> 2.9916667 | K3: Unidade sai R$3,50 | L3: https://www.distribuidorajcf.com.br/cilios-posticos
A4: Brasil | B4: Cílios | C4: Tufinho / cluster | D4: Zaxapp (Atacadista Max / L L) | E4: Tufos 6D mink - kit 10 caixas | F4: - | G4: 10 | H4: 47.99 | I4: =H4/G4 -> 4.799 | J4: =I4*IF(A4="China",$O$2,1) -> 4.799 | K4: Preço do kit, sem marca informada | L4: https://www.zaxapp.com.br/beleza/olhos-atacado/cilios-posticos-olhos-atacado | N4: Estimativa para frete aéreo + impostos de importação (II, IPI, PIS/COFINS, ICMS) + despachante em pedidos pequenos.
A5: Brasil | B5: Cílios | C5: Tufinho / cluster | D5: Zaxapp (Atacadista Max / L L) | E5: Extensão tufinho - kit 12 caixas | F5: - | G5: 12 | H5: 139.99 | I5: =H5/G5 -> 11.665833 | J5: =I5*IF(A5="China",$O$2,1) -> 11.665833 | K5: Caixa grande | L5: https://www.zaxapp.com.br/beleza/olhos-atacado/cilios-posticos-olhos-atacado | N5: 1,9x é uma premissa minha, não cotação: ajuste com o valor do seu despachante. Em volume (frete marítimo) tende a cair.
A6: Brasil | B6: Cílios | C6: Kit completo | D6: Zaxapp (Atacadista Max / L L) | E6: Kit tufos + pinça + cola + selante - 12 caixas | F6: - | G6: 12 | H6: 199.99 | I6: =H6/G6 -> 16.665833 | J6: =I6*IF(A6="China",$O$2,1) -> 16.665833 | K6: Mais barato que o kit Dafu (R$20) | L6: https://www.zaxapp.com.br/beleza/olhos-atacado/cilios-posticos-olhos-atacado | N6: Preços China = Alibaba em R$, FOB, 22/10/2026, sem frete. Preços Brasil = sites em 22/10/2026, sem frete.
A7: Brasil | B7: Cílios | C7: Postiço em tira | D7: Maquiagem Atacado (SP) | E7: Cílios postiços B13/B05 - box 10 un | F7: Blue Moon | G7: 10 | H7: 15 | I7: =H7/G7 -> 1.5 | J7: =I7*IF(A7="China",$O$2,1) -> 1.5 | K7: R$1,50 o par | L7: https://www.maquiagematacado.com.br/cilios-posticos | N7: Esmalte/gel são cosméticos: para revender importado direto é preciso importador com regularização na Anvisa.
A8: Brasil | B8: Cílios | C8: Postiço em tira | D8: Distribuidora JCF | E8: Cílios postiços 3D MC018 - 10 un | F8: Mandala | G8: 10 | H8: 29.9 | I8: =H8/G8 -> 2.99 | J8: =I8*IF(A8="China",$O$2,1) -> 2.99 | L8: https://www.distribuidorajcf.com.br/cilios-posticos
A9: Brasil | B9: Cílios | C9: Postiço em tira | D9: Distribuidora JCF | E9: Cílios Day by Day SPC02 - 10 un | F9: SP Colors | G9: 10 | H9: 40.9 | I9: =H9/G9 -> 4.09 | J9: =I9*IF(A9="China",$O$2,1) -> 4.09 | L9: https://www.distribuidorajcf.com.br/cilios-posticos
A10: Brasil | B10: Cílios | C10: Postiço em tira | D10: Distribuidora JCF | E10: Cílios 8D SP3408 - 10 un | F10: Sabrina Sato | G10: 10 | H10: 53.8 | I10: =H10/G10 -> 5.38 | J10: =I10*IF(A10="China",$O$2,1) -> 5.38 | K10: Marca forte | L10: https://www.distribuidorajcf.com.br/cilios-posticos
A11: Brasil | B11: Cílios | C11: Postiço em tira | D11: Maquiagem Atacado (SP) | E11: Cílios 5 pares ML225 | F11: Make Lolita | G11: 1 | H11: 5.26 | I11: =H11/G11 -> 5.26 | J11: =I11*IF(A11="China",$O$2,1) -> 5.26 | K11: Cartela com 5 pares | L11: https://www.maquiagematacado.com.br/cilios-posticos
A12: Brasil | B12: Cílios | C12: Extensão fio a fio | D12: Mercado Cílios (atacarejo) | E12: Fios YY Flying | F12: Nagaraku | G12: 1 | H12: 20.55 | I12: =H12/G12 -> 20.55 | J12: =I12*IF(A12="China",$O$2,1) -> 20.55 | K12: Pedido mín. R$300; cadastro VIP acima de R$1.000 | L12: https://mercadocilios.com.br/
A13: Brasil | B13: Cílios | C13: Extensão fio a fio | D13: Mercado Cílios (atacarejo) | E13: 5D W volume egípcio | F13: Nagaraku | G13: 1 | H13: 28.29 | I13: =H13/G13 -> 28.29 | J13: =I13*IF(A13="China",$O$2,1) -> 28.29 | K13: Pedido mín. R$300 | L13: https://mercadocilios.com.br/
A14: Brasil | B14: Cílios | C14: Extensão fio a fio | D14: Mercado Cílios (atacarejo) | E14: 5D W shape | F14: DeceMars | G14: 1 | H14: 37.75 | I14: =H14/G14 -> 37.75 | J14: =I14*IF(A14="China",$O$2,1) -> 37.75 | K14: Pedido mín. R$300 | L14: https://mercadocilios.com.br/
A15: Brasil | B15: Cílios | C15: Cola | D15: Maquiagem Atacado (SP) | E15: Cola Eye branca JS002 - kit 6 | F15: Eye | G15: 6 | H15: 21 | I15: =H15/G15 -> 3.5 | J15: =I15*IF(A15="China",$O$2,1) -> 3.5 | K15: Mesma cola que a Zhang vende a R$1,66 | L15: https://www.maquiagematacado.com.br/cilios-posticos
A16: Brasil | B16: Cílios | C16: Cola | D16: Distribuidora JCF | E16: Cola à prova d'água MF7038 - 12 un | F16: Miss France | G16: 12 | H16: 48 | I16: =H16/G16 -> 4 | J16: =I16*IF(A16="China",$O$2,1) -> 4 | L16: https://www.distribuidorajcf.com.br/cilios-posticos
A17: Brasil | B17: Cílios | C17: Cola | D17: Distribuidora JCF | E17: Cola transparente LN1100231 - 12 un | F17: Lua e Neve | G17: 12 | H17: 64.8 | I17: =H17/G17 -> 5.4 | J17: =I17*IF(A17="China",$O$2,1) -> 5.4 | L17: https://www.distribuidorajcf.com.br/cilios-posticos
A18: Brasil | B18: Unhas | C18: Unha postiça | D18: Zaxapp (Atacadista Max / L L) | E18: Unhas decoradas glitter degradê - 12 caixas | F18: - | G18: 12 | H18: 27.99 | I18: =H18/G18 -> 2.3325 | J18: =I18*IF(A18="China",$O$2,1) -> 2.3325 | K18: Preço do kit de 12 caixas | L18: https://www.zaxapp.com.br/beleza/unhas-atacado
A19: Brasil | B19: Unhas | C19: Unha postiça | D19: Zaxapp (Atacadista Max / L L) | E19: Unhas coloridas com adesivo - 12 caixas | F19: - | G19: 12 | H19: 29.99 | I19: =H19/G19 -> 2.4991667 | J19: =I19*IF(A19="China",$O$2,1) -> 2.4991667 | K19: Preço do kit de 12 caixas | L19: https://www.zaxapp.com.br/beleza/unhas-atacado
A20: Brasil | B20: Unhas | C20: Unha postiça | D20: Zaxapp (Atacadista Max / L L) | E20: Unhas decoradas strass flor 3D - 12 | F20: - | G20: 12 | H20: 34.99 | I20: =H20/G20 -> 2.9158333 | J20: =I20*IF(A20="China",$O$2,1) -> 2.9158333 | L20: https://www.zaxapp.com.br/beleza/unhas-atacado
A21: Brasil | B21: Unhas | C21: Unha postiça | D21: Distribuidora JCF | E21: Unha postiça arredondada/bailarina - 12 un | F21: Hello Mini | G21: 12 | H21: 48 | I21: =H21/G21 -> 4 | J21: =I21*IF(A21="China",$O$2,1) -> 4 | L21: https://www.distribuidorajcf.com.br/maos-pes
A22: Brasil | B22: Unhas | C22: Unha postiça | D22: Distribuidora JCF | E22: Kit 100 unhas bailarina MU1007 - 12 kits | F22: Meilys | G22: 12 | H22: 102.9 | I22: =H22/G22 -> 8.575 | J22: =I22*IF(A22="China",$O$2,1) -> 8.575 | K22: Cada kit tem 100 unhas | L22: https://www.distribuidorajcf.com.br/maos-pes
A23: Brasil | B23: Unhas | C23: Cola | D23: Zaxapp (Atacadista Max / L L) | E23: Cola de unha com pincel 10g - 12 frascos | F23: - | G23: 12 | H23: 27.99 | I23: =H23/G23 -> 2.3325 | J23: =I23*IF(A23="China",$O$2,1) -> 2.3325 | L23: https://www.zaxapp.com.br/beleza/unhas-atacado
A24: Brasil | B24: Unhas | C24: Cola | D24: Zaxapp (Atacadista Max / L L) | E24: Cola unha postiça 3g - 20 frascos | F24: - | G24: 20 | H24: 19.99 | I24: =H24/G24 -> 0.9995 | J24: =I24*IF(A24="China",$O$2,1) -> 0.9995 | K24: R$1,00 o frasco | L24: https://www.zaxapp.com.br/beleza/unhas-atacado
A25: China | B25: Cílios | C25: Extensão fio a fio | D25: Qingdao Fadvan Cosmetics (fábrica) | E25: Bandeja YY (Fadvan) | F25: Fadvan | G25: 1 | H25: 5.26 | I25: =H25/G25 -> 5.26 | J25: =I25*IF(A25="China",$O$2,1) -> 9.994 | K25: FOB R$5,26-6,70; mín. 2 un; 13 mil vendidos | L25: https://www.alibaba.com/trade/search?SearchText=yy+lashes+extension+tray
A26: China | B26: Cílios | C26: Extensão fio a fio | D26: Qingdao Fadvan Cosmetics (fábrica) | E26: Bandeja YW / 3D-5D W (Fadvan) | F26: Fadvan | G26: 1 | H26: 6.44 | I26: =H26/G26 -> 6.44 | J26: =I26*IF(A26="China",$O$2,1) -> 12.236 | K26: FOB R$6,44-8,19; mín. 10 un | L26: https://www.alibaba.com/trade/search?SearchText=yy+lashes+extension+tray
A27: China | B27: Cílios | C27: Extensão fio a fio | D27: Guangdong Jeleap | E27: Bandeja YY 0.05/0.07 | F27: - | G27: 1 | H27: 10.71 | I27: =H27/G27 -> 10.71 | J27: =I27*IF(A27="China",$O$2,1) -> 20.349 | K27: FOB R$10,71-11,74; mín. 10 | L27: https://www.alibaba.com/trade/search?SearchText=yy+lashes+extension+tray
A28: China | B28: Cílios | C28: Tufinho / cluster | D28: Qingdao Tinana | E28: Caixa clusters DIY | F28: - | G28: 1 | H28: 5.1 | I28: =H28/G28 -> 5.1 | J28: =I28*IF(A28="China",$O$2,1) -> 9.69 | K28: FOB R$5,10-12,82; mín. 5 caixas | L28: https://www.alibaba.com/trade/search?SearchText=diy+cluster+lashes+box+wholesale
A29: China | B29: Cílios | C29: Tufinho / cluster | D29: Qingdao Dinghai Hengtong | E29: Livro de clusters DIY grande | F29: - | G29: 1 | H29: 10.25 | I29: =H29/G29 -> 10.25 | J29: =I29*IF(A29="China",$O$2,1) -> 19.475 | K29: FOB R$10,25-13,34; mín. 2 caixas | L29: https://www.alibaba.com/trade/search?SearchText=diy+cluster+lashes+box+wholesale
A30: China | B30: Unhas | C30: Unha postiça | D30: Guangzhou Chengtu | E30: Caixa 24 unhas degradê com cola | F30: - | G30: 1 | H30: 2.32 | I30: =H30/G30 -> 2.32 | J30: =I30*IF(A30="China",$O$2,1) -> 4.408 | K30: FOB R$2,32-2,58; mín. 20 caixas | L30: https://www.alibaba.com/trade/search?SearchText=press+on+nails+24pcs+box+wholesale
A31: China | B31: Unhas | C31: Unha postiça | D31: Yiwu Lulu | E31: Caixa 24 unhas pintadas | F31: - | G31: 1 | H31: 2.63 | I31: =H31/G31 -> 2.63 | J31: =I31*IF(A31="China",$O$2,1) -> 4.997 | K31: FOB; mín. 12 caixas | L31: https://www.alibaba.com/trade/search?SearchText=press+on+nails+24pcs+box+wholesale
A32: China | B32: Unhas | C32: Unha postiça | D32: Guangzhou Mazy | E32: Caixa 24 unhas lisas (40 cores) | F32: - | G32: 1 | H32: 3.81 | I32: =H32/G32 -> 3.81 | J32: =I32*IF(A32="China",$O$2,1) -> 7.239 | K32: FOB R$3,81-4,64; mín. 3 | L32: https://www.alibaba.com/trade/search?SearchText=press+on+nails+24pcs+box+wholesale
A33: China | B33: Unhas | C33: Esmalte em gel | D33: Guangdong Baizhilin (BOZLIN) | E33: Esmalte em gel 15ml | F33: BOZLIN | G33: 1 | H33: 3.09 | I33: =H33/G33 -> 3.09 | J33: =I33*IF(A33="China",$O$2,1) -> 5.871 | K33: FOB R$3,09-4,90. Cosmético: exige regularização Anvisa para revender | L33: https://www.alibaba.com/trade/search?SearchText=uv+gel+nail+polish+15ml+wholesale
A34: China | B34: Unhas | C34: Esmalte em gel | D34: Guangzhou ICE Cosmetic | E34: Esmalte em gel UV | F34: - | G34: 1 | H34: 5.62 | I34: =H34/G34 -> 5.62 | J34: =I34*IF(A34="China",$O$2,1) -> 10.678 | K34: FOB R$5,62-7,62; mín. 100. Exige Anvisa | L34: https://www.alibaba.com/trade/search?SearchText=uv+gel+nail+polish+15ml+wholesale
A35: Brasil | B35: Unhas | C35: Esmalte em gel | D35: Fonte da Beleza (importadora, SP) | E35: Esmalte em gel (cores, dúzia) | F35: Kiss She e outras | G35: 12 | H35: 60 | I35: =H35/G35 -> 5 | J35: =I35*IF(A35="China",$O$2,1) -> 5 | K35: pág. 34 | L35: Catálogo Fonte Nail Design 21/09/2026 (PDF)
... A42: Brasil | B42: Unhas | C42: Preparação / base / top | D42: Fonte da Beleza (importadora, SP) | E42: Prep 500ml | F42: X&D | G42: 1 | H42: 9 | I42: =H42/G42 -> 9 | J42: =I42*IF(A42="China",$O$2,1) -> 9 | K42: 1 litro R$12 | L42: Catálogo Fonte Nail Design 21/09/2026 (PDF)
A43: Brasil | B43: Unhas | C43: Preparação / base / top | D43: Fonte da Beleza (importadora, SP) | E43: Removedor de gel (magic remover) | F43: - | G43: 12 | H43: 120 | I43: =H43/G43 -> 10 | J43: =I43*IF(A43="China",$O$2,1) -> 10 | L43: Catálogo Fonte Nail Design 21/09/2026 (PDF)
A44: Brasil | B44: Unhas | C44: Unha postiça | D44: Fonte da Beleza (importadora, SP) | E44: Tips - caixa 120 unidades | F44: Vinsall / Honey Girl | G44: 12 | H44: 72 | I44: =H44/G44 -> 6 | J44: =I44*IF(A44="China",$O$2,1) -> 6 | K44: Tips para alongamento, não press-on | L44: Catálogo Fonte Nail Design 21/09/2026 (PDF)
A45: Brasil | B45: Unhas | C45: Unha postiça | D45: Fonte da Beleza (importadora, SP) | E45: Soft gel tips - caixa 200 unidades | F45: Vinsall | G45: 12 | H45: 156 | I45: =H45/G45 -> 13 | J45: =I45*IF(A45="China",$O$2,1) -> 13 | L45: Catálogo Fonte Nail Design 21/09/2026 (PDF)
A46: Brasil | B46: Unhas | C46: Cuidados | D46: Fonte da Beleza (importadora, SP) | E46: Óleo de cutícula caneta | F46: - | G46: 12 | H46: 24 | I46: =H46/G46 -> 2 | J46: =I46*IF(A46="China",$O$2,1) -> 2 | K46: Dafu R$2,33 | L46: Catálogo Fonte Nail Design 21/09/2026 (PDF)
...

Sheet Dafu
A1: Categoria | B1: Subcategoria | C1: Produto | D1: Código(s) | E1: Unid. por lote | F1: Preço do lote (R$) | G1: Obs. | H1: Preço unit. (R$) | I1: Preço unit. c/ 8% cx fechada | J1: Preço de venda pretendido (R$) | K1: Margem s/ venda | M1: Desconto cx fechada
A2: Cílios | B2: Extensão fio a fio | C2: Fadvan YY (volume brasileiro) | D2: DF114-FF02; FF01-8/9/10/11/14 | E2: 10 | F2: 110 | G2: Tamanhos/curvaturas variados | H2: 11 | I2: =H2*(1-$N$2) -> 10.12 | K2: =IF(N(J2)=0,"",(J2-I2)/J2) | M2: Dafu | N2: 0.08
A3: Cílios | B3: Extensão fio a fio | C3: Fadvan U-Shape YY | D3: DF114-FF29 | E3: 10 | F3: 120 | H3: 12 | I3: =H3*(1-$N$2) -> 11.04 | K3: =IF(N(J3)=0,"",(J3-I3)/J3)
A4: Cílios | B4: Extensão fio a fio | C4: Fadvan M 12 linhas YY | D4: DF114-FF26 | E4: 10 | F4: 140 | H4: 14 | I4: =H4*(1-$N$2) -> 12.88 | K4: =IF(N(J4)=0,"",(J4-I4)/J4) | M4: Preencha a coluna amarela (J) com o seu preço de venda para ver a margem.
A5: Cílios | B5: Extensão fio a fio | C5: Fadvan 3DW | D5: DF114-FF24; FF03-8/9/10/12/13/14 | E5: 10 | F5: 150 | H5: 15 | I5: =H5*(1-$N$2) -> 13.8 | K5: =IF(N(J5)=0,"",(J5-I5)/J5) | M5: Fonte: catálogos Dafu (pasta NOVA DAFU CATALOGO, out/2026).
A6: Cílios | B6: Extensão fio a fio | C6: Fadvan Double Layer 3DW | D6: DF114-FF09 | E6: 10 | F6: 180 | H6: 18 | I6: =H6*(1-$N$2) -> 16.56 | K6: =IF(N(J6)=0,"",(J6-I6)/J6)
A7: Cílios | B7: Extensão fio a fio | C7: Fadvan 4DW | D7: DF114-FF04; FF04-9/10/11/12/13/14 | E7: 10 | F7: 190 | G7: FF04-8 sai R$22 | H7: 19 | I7: =H7*(1-$N$2) -> 17.48 | K7: =IF(N(J7)=0,"",(J7-I7)/J7)
A8: Cílios | B8: Extensão fio a fio | C8: Fadvan Double Layer 4DW | D8: DF114-FF10 | E8: 10 | F8: 200 | H8: 20 | I8: =H8*(1-$N$2) -> 18.4 | K8: =IF(N(J8)=0,"",(J8-I8)/J8)
A9: Cílios | B9: Extensão fio a fio | C9: Fadvan 5DW | D9: DF114-FF06; FF05-8/9/10/13/14 | E9: 10 | F9: 200 | H9: 20 | I9: =H9*(1-$N$2) -> 18.4 | K9: =IF(N(J9)=0,"",(J9-I9)/J9)
A10: Cílios | B10: Extensão fio a fio | C10: Fadvan M 12 linhas 5DW | D10: DF114-FF28 | E10: 10 | F10: 220 | H10: 22 | I10: =H10*(1-$N$2) -> 20.24 | K10: =IF(N(J10)=0,"",(J10-I10)/J10)
A11: Cílios | B11: Extensão fio a fio | C11: DeceMars YY / UYY (8-14mm e mix) | D11: DM-MYY01; DM-UYY8/11/13/14/01 | E11: 10 | F11: 120 | H11: 12 | I11: =H11*(1-$N$2) -> 11.04 | K11: =IF(N(J11)=0,"",(J11-I11)/J11)
A12: Cílios | B12: Extensão fio a fio | C12: DeceMars 4DW | D12: DM-4D9; 4D10; 4D14 | E12: 10 | F12: 165 | H12: 16.5 | I12: =H12*(1-$N$2) -> 15.18 | K12: =IF(N(J12)=0,"",(J12-I12)/J12)
A13: Cílios | B13: Extensão fio a fio | C13: DeceMars 5DW (inclui marrom mix) | D13: DM-5D8; 5D10; 5D12; 5D02 | E13: 10 | F13: 200 | G13: DM-5D9 sai R$22 | H13: 20 | I13: =H13*(1-$N$2) -> 18.4 | K13: =IF(N(J13)=0,"",(J13-I13)/J13)
A14: Cílios | B14: Extensão fio a fio | C14: DeceMars 6D | D14: DM-6D8; 6D9; 6D13 | E14: 10 | F14: 180 | H14: 18 | I14: =H14*(1-$N$2) -> 16.56 | K14: =IF(N(J14)=0,"",(J14-I14)/J14)
A15: Cílios | B15: Tufinho / cluster | C15: Tufinho tira simples | D15: DF107-FF18 | E15: 12 | F15: 12 | G15: Item muito barato - conferir o que é | H15: 1 | I15: =H15*(1-$N$2) -> 0.92 | K15: =IF(N(J15)=0,"",(J15-I15)/J15)
A16: Cílios | B16: Tufinho / cluster | C16: Tufinho 4 tamanhos 8-14mm | D16: DF107-FF24-8~14 | E16: 10 | F16: 36 | H16: 3.6 | I16: =H16*(1-$N$2) -> 3.312 | K16: =IF(N(J16)=0,"",(J16-I16)/J16)
A17: Cílios | B17: Tufinho / cluster | C17: Tufinho caixa pequena | D17: DF108-FF0102-1/2 | E17: 10 | F17: 42 | H17: 4.2 | I17: =H17*(1-$N$2) -> 3.864 | K17: =IF(N(J17)=0,"",(J17-I17)/J17)
A18: Cílios | B18: Tufinho / cluster | C18: Tufinho caixa | D18: DF107-FF84 | E18: 10 | F18: 45 | H18: 4.5 | I18: =H18*(1-$N$2) -> 4.14 | K18: =IF(N(J18)=0,"",(J18-I18)/J18)
A19: Cílios | B19: Tufinho / cluster | C19: Tufinho caixa (catálogo mostra lote divergente) | D19: DF107-FF31; FF89 | E19: 12 | F19: 54 | G19: Catálogo traz lote R$45/R$72 - confirmar | H19: 4.5 | I19: =H19*(1-$N$2) -> 4.14 | K19: =IF(N(J19)=0,"",(J19-I19)/J19)
A20: Cílios | B20: Tufinho / cluster | C20: Tufinho 20P/30P/40P | D20: DF107-FF85; FF86; FF60 | E20: 10 | F20: 50 | H20: 5 | I20: =H20*(1-$N$2) -> 4.6 | K20: =IF(N(J20)=0,"",(J20-I20)/J20)
A21: Cílios | B21: Tufinho / cluster | C21: Tufinho caixa | D21: DF107-FF79; FF80 | E21: 12 | F21: 60 | H21: 5 | I21: =H21*(1-$N$2) -> 4.6 | K21: =IF(N(J21)=0,"",(J21-I21)/J21)
A22: Cílios | B22: Tufinho / cluster | C22: Tufinho caixa | D22: DF107-FF81 | E22: 10 | F22: 55 | H22: 5.5 | I22: =H22*(1-$N$2) -> 5.06 | K22: =IF(N(J22)=0,"",(J22-I22)/J22)
A23: Cílios | B23: Tufinho / cluster | C23: Tufinho caixa média | D23: DF107-FF109 a FF113; FF121; FF122 | E23: 12 | F23: 66 | H23: 5.5 | I23: =H23*(1-$N$2) -> 5.06 | K23: =IF(N(J23)=0,"",(J23-I23)/J23)
A24: Cílios | B24: Tufinho / cluster | C24: Tufinho caixa média | D24: DF107-FF123; FF87 | E24: 12 | F24: 72 | H24: 6 | I24: =H24*(1-$N$2) -> 5.52 | K24: =IF(N(J24)=0,"",(J24-I24)/J24)
A25: Cílios | B25: Tufinho / cluster | C25: Tufinho caixa decorada (sem fios) | D25: 108-FF05/07/08/09/10; DF108-FF0205-1/4 | E25: 12 | F25: 78 | H25: 6.5 | I25: =H25*(1-$N$2) -> 5.98 | K25: =IF(N(J25)=0,"",(J25-I25)/J25)
A26: Cílios | B26: Tufinho / cluster | C26: Tufinho blister grande | D26: DF105-FF05; FF06; FF07 | E26: 10 | F26: 72 | H26: 7.2 | I26: =H26*(1-$N$2) -> 6.624 | K26: =IF(N(J26)=0,"",(J26-I26)/J26)
A27: Cílios | B27: Tufinho / cluster | C27: Extensão em casa | D27: 108-FF13 | E27: 12 | F27: 96 | H27: 8 | I27: =H27*(1-$N$2) -> 7.36 | K27: =IF(N(J27)=0,"",(J27-I27)/J27)
A28: Cílios | B28: Tufinho / cluster | C28: Tufinho mega caixa | D28: DF107-FF92; FF52; FF51; FF53; FF19; FF20 | E28: 12 | F28: 115 | H28: 9.58 | I28: =H28*(1-$N$2) -> 8.8136 | K28: =IF(N(J28)=0,"",(J28-I28)/J28)
A29: Cílios | B29: Tufinho / cluster | C29: Tufinho mega caixa | D29: DF107-FF124; FF55; FF57; FF58; FF21; 108-FF11/12/14; AD4919-SR131 | E29: 12 | F29: 120 | H29: 10 | I29: =H29*(1-$N$2) -> 9.2 | K29: =IF(N(J29)=0,"",(J29-I29)/J29)
A30: Cílios | B30: Tufinho / cluster | C30: Tufinho mega caixa | D30: DF107-FF125 a FF128; FF115; FF116; FF41; FF90; FF96; 118-FF07/09/10; AD4909-SR071 | E30: 12 | F30: 132 | H30: 11 | I30: =H30*(1-$N$2) -> 10.12 | K30: =IF(N(J30)=0,"",(J30-I30)/J30)
A31: Cílios | B31: Tufinho / cluster | C31: Tufinho mega caixa | D31: DF107-FF120 | E31: 12 | F31: 138 | H31: 11.5 | I31: =H31*(1-$N$2) -> 10.58 | K31: =IF(N(J31)=0,"",(J31-I31)/J31)
... A40: Cílios | B40: Cola | C40: Cola de cílios Cola (branca/preta) | D40: DF-CL017; DF-CL018 | E40: 12 | F40: 54 | H40: 4.5 | I40: =H40*(1-$N$2) -> 4.14 | K40: =IF(N(J40)=0,"",(J40-I40)/J40)
A41: Cílios | B41: Cola | C41: Cola extensão (frasco) | D41: DF101CL353; CL354; CL355 | E41: 1 | F41: 5 | G41: Vendido por unidade | H41: 5 | I41: =H41*(1-$N$2) -> 4.6 | K41: =IF(N(J41)=0,"",(J41-I41)/J41)
A42: Cílios | B42: Cola | C42: Cola extensão Axxl (frasco) | D42: DF101CL357 | E42: 1 | F42: 10 | G42: Vendido por unidade | H42: 10 | I42: =H42*(1-$N$2) -> 9.2 | K42: =IF(N(J42)=0,"",(J42-I42)/J42)
A43: Cílios | B43: Removedor | C43: Removedor Salon Pro | D43: DF101CL356 | E43: 1 | F43: 7 | G43: Vendido por unidade | H43: 7 | I43: =H43*(1-$N$2) -> 6.44 | K43: =IF(N(J43)=0,"",(J43-I43)/J43)
A44: Cílios | B44: Removedor | C44: Removedor caneta 10ml | D44: DF101-CL341 | E44: 12 | F44: 78 | H44: 6.5 | I44: =H44*(1-$N$2) -> 5.98 | K44: =IF(N(J44)=0,"",(J44-I44)/J44)
A45: Cílios | B45: Removedor | C45: Removedor (caixa) | D45: DF-RM01 | E45: 12 | F45: 96 | H45: 8 | I45: =H45*(1-$N$2) -> 7.36 | K45: =IF(N(J45)=0,"",(J45-I45)/J45)
A46: Cílios | B46: Acessório | C46: Suporte acrílico para bandejas | D46: DF101-PC368 | E46: 1 | F46: 15 | H46: 15 | I46: =H46*(1-$N$2) -> 13.8 | K46: =IF(N(J46)=0,"",(J46-I46)/J46)
A47: Unhas | B47: Unha postiça | C47: Unha postiça básica | D47: 7-UN2079 | E47: 12 | F47: 22 | G47: Novidade 21/10: R$2,00 | H47: 1.83 | I47: =H47*(1-$N$2) -> 1.6836 | K47: =IF(N(J47)=0,"",(J47-I47)/J47)
A48: Unhas | B48: Unha postiça | C48: Unha postiça | D48: 379-UN0205-1/5 | E48: 12 | F48: 24 | H48: 2 | I48: =H48*(1-$N$2) -> 1.84 | K48: =IF(N(J48)=0,"",(J48-I48)/J48)
...

Sheet Zhang
A1: Categoria | B1: Subcategoria | C1: Produto (como está no site) | D1: Código | E1: Preço unit. (R$) | F1: Preço de venda pretendido (R$) | G1: Margem s/ venda | I1: Fonte: zhangmaquiagem.com.br, campo 'preço unidade', 22/10/2026. Venda em caixa (c/6, c/10, c/12, c/24).
A2: Cílios | B2: Postiço em tira | C2: cilios amor angel 1 pare c/24pcs | D2: 5D-08 | E2: 3.5 | G2: =IF(N(F2)=0,"",(F2-E2)/F2)
A3: Cílios | B3: Postiço em tira | C3: CILIOS AMOR ANJA 1 PAR C/24PCS | D3: 5D-107 | E3: 3.5 | G3: =IF(N(F3)=0,"",(F3-E3)/F3)
A4: Cílios | B4: Postiço em tira | C4: cilios amor anjo | D4: AA-5D-51 | E4: 7.25 | G4: =IF(N(F4)=0,"",(F4-E4)/F4)
A5: Cílios | B5: Postiço em tira | C5: cilios amor anjo | D5: AA-5D-56 | E5: 7.25 | G5: =IF(N(F5)=0,"",(F5-E5)/F5)
A6: Cílios | B6: Postiço em tira | C6: CILIOS AMOR ANJO | D6: 5D-41 | E6: 3.5 | G6: =IF(N(F6)=0,"",(F6-E6)/F6)
A7: Cílios | B7: Postiço em tira | C7: CILIOS AMOR ANJO 5PAR | D7: 5D-10 | E7: 9 | G7: =IF(N(F7)=0,"",(F7-E7)/F7)
A8: Cílios | B8: Postiço em tira | C8: CILIOS AMOR ANJO 5PAR | D8: 5D-23 | E8: 9 | G8: =IF(N(F8)=0,"",(F8-E8)/F8)
A9: Cílios | B9: Postiço em tira | C9: cilios amor anjo C/5 | D9: 5D-12 | E9: 9 | G9: =IF(N(F9)=0,"",(F9-E9)/F9)
A10: Cílios | B10: Postiço em tira | C10: cilios amor anjo C/5 | D10: 5D-14 | E10: 9 | G10: =IF(N(F10)=0,"",(F10-E10)/F10)
A11: Cílios | B11: Postiço em tira | C11: cilios amor anjo C/5 | D11: 5D-21 | E11: 9 | G11: =IF(N(F11)=0,"",(F11-E11)/F11)
A12: Cílios | B12: Postiço em tira | C12: cilios amor anjo C/5 | D12: 5D-26 | E12: 9 | G12: =IF(N(F12)=0,"",(F12-E12)/F12)
A13: Cílios | B13: Postiço em tira | C13: cilios amor anjo C/5 | D13: 5D-28 | E13: 9 | G13: =IF(N(F13)=0,"",(F13-E13)/F13)
... A144: Unhas | B144: Unha postiça | C144: UNHASPOSTICAS RUBI | D144: UP511 | E144: 8.5 | G144: =IF(N(F144)=0,"",(F144-E144)/F144)

Sheet Referencia
A1: Categoria | B1: Subcategoria | C1: Produto (varejo) | D1: Preço varejo (R$) | E1: Onde | F1: Link
A2: Cílios | B2: Extensão fio a fio | C2: Fadvan YY mix (1 bandeja) | D2: 25.49 | E2: Mercado Livre (promo set/2026, de R$30,99) | F2: https://descontostop.com/promocao/extensao-de-cilios-fadvan-y-volume-brasileiro-mix-e-unitario
A3: Cílios | B3: Extensão fio a fio | C3: Fadvan YY - kit 5 bandejas (por bandeja) | D3: 19.8 | E3: Shopee (kit 5 por R$98,99) | F3: https://melhoraopreco.com.br/ofertas/shopee/7154957
A4: Cílios | B4: Extensão fio a fio | C4: Fadvan W 5D (1 bandeja) | D4: 47.41 | E4: Magazine Luiza | F4: https://www.magazineluiza.com.br/busca/cilios/
A5: Cílios | B5: Tufinho / cluster | C5: Tufinho New Show clássico 20P | D5: 19 | E5: Magazine Luiza | F5: https://m.magazineluiza.com.br/busca/kit+cilios/
A6: Cílios | B6: Tufinho / cluster | C6: Tufinho Sabrina Sato 30P | D6: 15.68 | E6: Magazine Luiza | F6: https://www.magazineluiza.com.br/busca/cilios/
A7: Cílios | B7: Tufinho / cluster | C7: 60 tufinhos 30P 0.07 10mm | D7: 19.9 | E7: Magazine Luiza | F7: https://www.magazineluiza.com.br/busca/cilios/
A8: Cílios | B8: Kit completo | C8: Kit tufinho Sabrina Sato 20P + cola + pinça + removedor | D8: 32.55 | E8: Magazine Luiza | F8: https://www.magazineluiza.com.br/busca/cilios/
A9: Cílios | B9: Kit completo | C9: Kit DIY Fadvan 240 tufos + cola + pinça | D9: 29.99 | E9: Shopee (anúncio antigo) | F9: https://escorregaopreco.com.br/ofertas/shopee/5812317
A10: Unhas | B10: Esmalte em gel | C10: Esmalte em gel Dafu 10ml (unidade) | D10: 18.99 | E10: Magazine Luiza | F10: https://m.magazineluiza.com.br/busca/esmalte+dafu/
A11: Unhas | B11: Esmalte em gel | C11: Esmalte em gel Dafu Glamour 12ml | D11: 22.79 | E11: Magazine Luiza | F11: https://m.magazineluiza.com.br/busca/esmalte+dafu/
A12: Unhas | B12: Unha postiça | C12: Unha postiça 24un genérica | D12: 4.89 | E12: Shopee (anúncio antigo) | F12: https://www.escorregaopreco.com.br/ofertas/shopee/6917608
A14: Preços de varejo são anúncios pontuais (podem estar em promoção ou desatualizados) – servem só de teto de referência.
